{"name": "test_get_not_auth_user_orders_fail", "status": "passed", "description": "Получение списка заказов неавторизованным пользователем", "start": 1720287843218, "stop": 1720287843632, "uuid": "998252ac-8f24-4660-b9e5-44a7de9abd49", "historyId": "1643701cbd033c513624420bb28d21bc", "testCaseId": "1643701cbd033c513624420bb28d21bc", "fullName": "tests.test_get_user_orders.TestGetUserOrders#test_get_not_auth_user_orders_fail", "labels": [{"name": "parentSuite", "value": "tests"}, {"name": "suite", "value": "test_get_user_orders"}, {"name": "subSuite", "value": "TestGetUserOrders"}, {"name": "host", "value": "DESKTOP-LU3QF62"}, {"name": "thread", "value": "22836-MainThread"}, {"name": "framework", "value": "pytest"}, {"name": "language", "value": "cpython3"}, {"name": "package", "value": "tests.test_get_user_orders"}]}